Workbook

Sheet TaskDescription
B2: Task Description
B4: Background:
B6: Catering is one of Edinburgh Airport's largest commercial revenue streams and plays a key role in the airport's overall financial performance. The Commercial team regularly reviews the performance of the catering estate to understand how outlets are trading, identify trends over time, and highlight opportunities to improve performance. The team uses dashboards to monitor key performance indicators and support commercial decision making. You have been provided with a dataset containing monthly sales and transaction data for a number of catering outlets across the airport (tab, RetailerData). You have also been provided with the total passenger numbers (tab, PassengerData)
B15: Your Task:
B17: Create an Output tab to produce any outcomes. Use formulas (e.g. do not copy paste as values from pviots) so we can see your thought process. Create an interactive dashboard in Excel, PowerBI (or both) that enables the Commercial team to monitor the performance of the catering estate. Your dashboard should allow users to quickly understand: - Overall catering performance - Individual outlet performance - Year on Year trends - YTD performance - Any other analysis you believe to be useful Alongside your dashboard, provide a short summary (max. 5 bullet points) outlining your key findings

Sheet RetailerData
A1: Category1 | B1: Outlet Name | C1: Category4 | D1: Year of Month Start Date | E1: Month of Month Start Date | F1: Unit Location | G1: Monthly Unit Size Meter Sq | H1: Transactions | I1: Total Sales
A2: Catering | B2: Gate Bistro | C2: Coffee | D2: 2024 | E2: December | F2: Central | G2: 398 | H2: 6930.5961 | I2: 144744.88
D3: 2025 | E3: January | F3: Central | G3: 398 | H3: 9413.0198 | I3: 228691.06
E4: February | F4: Central | G4: 398 | H4: 17939.191 | I4: 199814.15
E5: March | F5: Central | G5: 398 | H5: 14655.715 | I5: 333749.49
E6: April | F6: Central | G6: 398 | H6: 16830.057 | I6: 281233.75
E7: May | F7: Central | G7: 398 | H7: 26165.643 | I7: 379231.63
E8: June | F8: Central | G8: 398 | H8: 25846.403 | I8: 445530.49
E9: July | F9: Central | G9: 398 | H9: 22873.303 | I9: 399964.7
E10: August | F10: Central | G10: 398 | H10: 17669.771 | I10: 388876.27
E11: September | F11: Central | G11: 398 | H11: 24593.184 | I11: 399015.51
E12: October | F12: Central | G12: 398 | H12: 16708.588 | I12: 359711.42
E13: November | F13: Central | G13: 398 | H13: 20735.487 | I13: 295193.05
E14: December | F14: Central | G14: 398 | H14: 19333.355 | I14: 289865.47
D15: 2026 | E15: January | F15: Central | G15: 398 | H15: 16111.933 | I15: 292270.14
E16: February | F16: Central | G16: 398 | H16: 15861.79 | I16: 235071.51
E17: March | F17: Central | G17: 398 | H17: 13741.487 | I17: 292012.16
E18: April | F18: Central | G18: 398 | H18: 16814.743 | I18: 233875.49
E19: May | F19: Central | G19: 398 | H19: 21858.441 | I19: 305511.04
E20: June | F20: Central | G20: 398 | H20: 24825.179 | I20: 285397.27
B21: Terminal Kitchen | C21: Restaurants | D21: 2024 | E21: January | F21: East | G21: 300 | H21: 29433.737 | I21: 283173.55
E22: February | F22: East | G22: 300 | H22: 33870.637 | I22: 317239.04
E23: March | F23: East | G23: 300 | H23: 25452.317 | I23: 406520.3
E24: April | F24: East | G24: 300 | H24: 32054.895 | I24: 434253.39
E25: May | F25: East | G25: 300 | H25: 33878.082 | I25: 348854.71
E26: June | F26: East | G26: 300 | H26: 45283.913 | I26: 593538.52
E27: July | F27: East | G27: 300 | H27: 37922.194 | I27: 577074.16
E28: August | F28: East | G28: 300 | H28: 38398.113 | I28: 5161021.2
E29: September | F29: East | G29: 300 | H29: 44501.744 | I29: 513874.15
E30: October | F30: East | G30: 300 | H30: 39423.334 | I30: 393650.67
E31: November | F31: East | G31: 300 | H31: 27129.848 | I31: 352104.35
E32: December | F32: East | G32: 300 | H32: 30912.306 | I32: 495902.21
D33: 2025 | E33: January | F33: East | G33: 300 | H33: 24750.495 | I33: 340380.21
E34: February | F34: East | G34: 300 | H34: 26229.901 | I34: 252247.12
E35: March | F35: East | G35: 300 | H35: 23377.561 | I35: 300082.7
E36: April | F36: East | G36: 300 | H36: 36302.335 | I36: 374099.27
E37: May | F37: East | G37: 300 | H37: 27423.5 | I37: 544318.32
E38: June | F38: East | G38: 300 | H38: 35533.293 | I38: 378073.99
E39: July | F39: East | G39: 300 | H39: 38449.315 | I39: 667406
E40: August | F40: East | G40: 300 | H40: 42503.813 | I40: 435838.28
...

Sheet PassengerData
B2: Month | C2: Jan | D2: Feb | E2: Mar | F2: Apr | G2: May | H2: Jun | I2: Jul | J2: Aug | K2: Sep | L2: Oct | M2: Nov | N2: Dec
B3: 2024Actual | C3: 895441 | D3: 948465 | E3: 1117311 | F3: 1284638 | G3: 1495297 | H3: 1561422 | I3: 1628915 | J3: 1618153 | K3: 1529718 | L3: 1468168 | M3: 1091165 | N3: 1153914
B4: 2025Actual | C4: 950595 | D4: 1016868 | E4: 1191178 | F4: 1393786 | G4: 1576429 | H4: 1643722 | I4: 1783169 | J4: 1770479 | K4: 1628996 | L4: 1609903 | M4: 1193998 | N4: 1222096
B5: 2026Actual | C5: 1017320 | D5: 1071937 | E5: 1274309 | F5: 1465123 | G5: 1655765 | H5: 1709032 | I5: 0 | J5: 0 | K5: 0 | L5: 0 | M5: 0 | N5: 0

Sheet Data
A1: Outlet | B1: Type | C1: Location | D1: Year | E1: Month | F1: MonthNum | G1: Sqm | H1: Transactions | I1: Total Sales | J1: ATV
A2: Gate Bistro | B2: Coffee | C2: Central | D2: 2024 | E2: December | F2: 12 | G2: 398 | H2: 6930.6 | I2: 144744.88 | J2: =IF(H2=0,0,I2/H2) -> 20.884899
A3: Gate Bistro | B3: Coffee | C3: Central | D3: 2025 | E3: January | F3: 1 | G3: 398 | H3: 9413.02 | I3: 228691.06 | J3: =IF(H3=0,0,I3/H3) -> 24.295185
A4: Gate Bistro | B4: Coffee | C4: Central | D4: 2025 | E4: February | F4: 2 | G4: 398 | H4: 17939.19 | I4: 199814.15 | J4: =IF(H4=0,0,I4/H4) -> 11.138415
A5: Gate Bistro | B5: Coffee | C5: Central | D5: 2025 | E5: March | F5: 3 | G5: 398 | H5: 14655.72 | I5: 333749.49 | J5: =IF(H5=0,0,I5/H5) -> 22.772644
A6: Gate Bistro | B6: Coffee | C6: Central | D6: 2025 | E6: April | F6: 4 | G6: 398 | H6: 16830.06 | I6: 281233.75 | J6: =IF(H6=0,0,I6/H6) -> 16.710205
A7: Gate Bistro | B7: Coffee | C7: Central | D7: 2025 | E7: May | F7: 5 | G7: 398 | H7: 26165.64 | I7: 379231.63 | J7: =IF(H7=0,0,I7/H7) -> 14.493497
A8: Gate Bistro | B8: Coffee | C8: Central | D8: 2025 | E8: June | F8: 6 | G8: 398 | H8: 25846.4 | I8: 445530.49 | J8: =IF(H8=0,0,I8/H8) -> 17.237623
A9: Gate Bistro | B9: Coffee | C9: Central | D9: 2025 | E9: July | F9: 7 | G9: 398 | H9: 22873.3 | I9: 399964.7 | J9: =IF(H9=0,0,I9/H9) -> 17.486095
A10: Gate Bistro | B10: Coffee | C10: Central | D10: 2025 | E10: August | F10: 8 | G10: 398 | H10: 17669.77 | I10: 388876.27 | J10: =IF(H10=0,0,I10/H10) -> 22.007998
A11: Gate Bistro | B11: Coffee | C11: Central | D11: 2025 | E11: September | F11: 9 | G11: 398 | H11: 24593.18 | I11: 399015.51 | J11: =IF(H11=0,0,I11/H11) -> 16.224641
A12: Gate Bistro | B12: Coffee | C12: Central | D12: 2025 | E12: October | F12: 10 | G12: 398 | H12: 16708.59 | I12: 359711.42 | J12: =IF(H12=0,0,I12/H12) -> 21.528532
A13: Gate Bistro | B13: Coffee | C13: Central | D13: 2025 | E13: November | F13: 11 | G13: 398 | H13: 20735.49 | I13: 295193.05 | J13: =IF(H13=0,0,I13/H13) -> 14.236126
... A123: North Kitchen | B123: Restaurants | C123: East | D123: 2026 | E123: June | F123: 6 | G123: 817 | H123: 118818.58 | I123: 1731529.4 | J123: =IF(H123=0,0,I123/H123) -> 14.572884

Sheet Output
A1: Output
A3: Full year sales
A4: Metric | B4: 2024 | C4: 2025 | D4: 2026
A5: Total Sales | B5: =SUMIFS(Data!$I$2:$I$123,Data!$D$2:$D$123,B$4) -> 26494374 | C5: =SUMIFS(Data!$I$2:$I$123,Data!$D$2:$D$123,C$4) -> 29272430 | D5: =SUMIFS(Data!$I$2:$I$123,Data!$D$2:$D$123,D$4) -> 14421758
A6: Total Transactions | B6: =SUMIFS(Data!$H$2:$H$123,Data!$D$2:$D$123,B$4) -> 1747639.3 | C6: =SUMIFS(Data!$H$2:$H$123,Data!$D$2:$D$123,C$4) -> 2216183.1 | D6: =SUMIFS(Data!$H$2:$H$123,Data!$D$2:$D$123,D$4) -> 1082252.7
A7: ATV | B7: =IF(B6=0,0,B5/B6) -> 15.160093 | C7: =IF(C6=0,0,C5/C6) -> 13.208489 | D7: =IF(D6=0,0,D5/D6) -> 13.325685
A8: (2026 is Jan-Jun only, so full-year 2026 is not comparable)
A10: YTD Jan-Jun (like-for-like)
A11: Metric | B11: 2024 | C11: 2025 | D11: 2026 | E11: YoY 25v24 | F11: YoY 26v25
A12: YTD Sales | B12: =SUMIFS(Data!$I$2:$I$123,Data!$D$2:$D$123,B$11,Data!$F$2:$F$123,"<=6") -> 10048159 | C12: =SUMIFS(Data!$I$2:$I$123,Data!$D$2:$D$123,C$11,Data!$F$2:$F$123,"<=6") -> 13255458 | D12: =SUMIFS(Data!$I$2:$I$123,Data!$D$2:$D$123,D$11,Data!$F$2:$F$123,"<=6") -> 14421758 | E12: =IF(B12=0,"",C12/B12-1) -> 0.31919261 | F12: =IF(C12=0,"",D12/C12-1) -> 0.087986464
A13: YTD Transactions | B13: =SUMIFS(Data!$H$2:$H$123,Data!$D$2:$D$123,B$11,Data!$F$2:$F$123,"<=6") -> 823543.03 | C13: =SUMIFS(Data!$H$2:$H$123,Data!$D$2:$D$123,C$11,Data!$F$2:$F$123,"<=6") -> 1015379.8 | D13: =SUMIFS(Data!$H$2:$H$123,Data!$D$2:$D$123,D$11,Data!$F$2:$F$123,"<=6") -> 1082252.7 | E13: =IF(B13=0,"",C13/B13-1) -> 0.23294083 | F13: =IF(C13=0,"",D13/C13-1) -> 0.065859955
A14: YTD ATV | B14: =IF(B13=0,0,B12/B13) -> 12.201135 | C14: =IF(C13=0,0,C12/C13) -> 13.054679 | D14: =IF(D13=0,0,D12/D13) -> 13.325685 | E14: =IF(B14=0,"",C14/B14-1) -> 0.069956137 | F14: =IF(C14=0,"",D14/C14-1) -> 0.020759302
A15: YTD Passengers | B15: =SUM(PassengerData!C3:H3) -> 7302574 | C15: =SUM(PassengerData!C4:H4) -> 7772578 | D15: =SUM(PassengerData!C5:H5) -> 8193486 | E15: =IF(B15=0,"",C15/B15-1) -> 0.064361416 | F15: =IF(C15=0,"",D15/C15-1) -> 0.054152946
A16: Spend per passenger | B16: =IF(B15=0,0,B12/B15) -> 1.375975 | C16: =IF(C15=0,0,C12/C15) -> 1.7054133 | D16: =IF(D15=0,0,D12/D15) -> 1.7601493 | E16: =IF(B16=0,"",C16/B16-1) -> 0.23942168 | F16: =IF(C16=0,"",D16/C16-1) -> 0.032095454
A18: Monthly total sales
A19: Month | B19: 2024 | C19: 2025 | D19: 2026
A20: Jan | B20: =SUMIFS(Data!$I$2:$I$123,Data!$D$2:$D$123,B$19,Data!$F$2:$F$123,1) -> 1285199.1 | C20: =SUMIFS(Data!$I$2:$I$123,Data!$D$2:$D$123,C$19,Data!$F$2:$F$123,1) -> 1513724.5 | D20: =SUMIFS(Data!$I$2:$I$123,Data!$D$2:$D$123,D$19,Data!$F$2:$F$123,1) -> 2109073.5
A21: Feb | B21: =SUMIFS(Data!$I$2:$I$123,Data!$D$2:$D$123,B$19,Data!$F$2:$F$123,2) -> 1191468.2 | C21: =SUMIFS(Data!$I$2:$I$123,Data!$D$2:$D$123,C$19,Data!$F$2:$F$123,2) -> 1733221.9 | D21: =SUMIFS(Data!$I$2:$I$123,Data!$D$2:$D$123,D$19,Data!$F$2:$F$123,2) -> 1827374.8
A22: Mar | B22: =SUMIFS(Data!$I$2:$I$123,Data!$D$2:$D$123,B$19,Data!$F$2:$F$123,3) -> 1320726.6 | C22: =SUMIFS(Data!$I$2:$I$123,Data!$D$2:$D$123,C$19,Data!$F$2:$F$123,3) -> 1760224.4 | D22: =SUMIFS(Data!$I$2:$I$123,Data!$D$2:$D$123,D$19,Data!$F$2:$F$123,3) -> 2276394.1
A23: Apr | B23: =SUMIFS(Data!$I$2:$I$123,Data!$D$2:$D$123,B$19,Data!$F$2:$F$123,4) -> 1632518.8 | C23: =SUMIFS(Data!$I$2:$I$123,Data!$D$2:$D$123,C$19,Data!$F$2:$F$123,4) -> 2526490.9 | D23: =SUMIFS(Data!$I$2:$I$123,Data!$D$2:$D$123,D$19,Data!$F$2:$F$123,4) -> 2184653.9
A24: May | B24: =SUMIFS(Data!$I$2:$I$123,Data!$D$2:$D$123,B$19,Data!$F$2:$F$123,5) -> 2066828.9 | C24: =SUMIFS(Data!$I$2:$I$123,Data!$D$2:$D$123,C$19,Data!$F$2:$F$123,5) -> 2629319.2 | D24: =SUMIFS(Data!$I$2:$I$123,Data!$D$2:$D$123,D$19,Data!$F$2:$F$123,5) -> 3190270.9
A25: Jun | B25: =SUMIFS(Data!$I$2:$I$123,Data!$D$2:$D$123,B$19,Data!$F$2:$F$123,6) -> 2551417.7 | C25: =SUMIFS(Data!$I$2:$I$123,Data!$D$2:$D$123,C$19,Data!$F$2:$F$123,6) -> 3092476.6 | D25: =SUMIFS(Data!$I$2:$I$123,Data!$D$2:$D$123,D$19,Data!$F$2:$F$123,6) -> 2833991.2
A26: Jul | B26: =SUMIFS(Data!$I$2:$I$123,Data!$D$2:$D$123,B$19,Data!$F$2:$F$123,7) -> 2006916.7 | C26: =SUMIFS(Data!$I$2:$I$123,Data!$D$2:$D$123,C$19,Data!$F$2:$F$123,7) -> 3296520.7
A27: Aug | B27: =SUMIFS(Data!$I$2:$I$123,Data!$D$2:$D$123,B$19,Data!$F$2:$F$123,8) -> 6760699.9 | C27: =SUMIFS(Data!$I$2:$I$123,Data!$D$2:$D$123,C$19,Data!$F$2:$F$123,8) -> 2435491
A28: Sep | B28: =SUMIFS(Data!$I$2:$I$123,Data!$D$2:$D$123,B$19,Data!$F$2:$F$123,9) -> 2056802.3 | C28: =SUMIFS(Data!$I$2:$I$123,Data!$D$2:$D$123,C$19,Data!$F$2:$F$123,9) -> 3227304.6
A29: Oct | B29: =SUMIFS(Data!$I$2:$I$123,Data!$D$2:$D$123,B$19,Data!$F$2:$F$123,10) -> 1751863.7 | C29: =SUMIFS(Data!$I$2:$I$123,Data!$D$2:$D$123,C$19,Data!$F$2:$F$123,10) -> 2847320.2
A30: Nov | B30: =SUMIFS(Data!$I$2:$I$123,Data!$D$2:$D$123,B$19,Data!$F$2:$F$123,11) -> 1786598.9 | C30: =SUMIFS(Data!$I$2:$I$123,Data!$D$2:$D$123,C$19,Data!$F$2:$F$123,11) -> 2064020.8
A31: Dec | B31: =SUMIFS(Data!$I$2:$I$123,Data!$D$2:$D$123,B$19,Data!$F$2:$F$123,12) -> 2083333.6 | C31: =SUMIFS(Data!$I$2:$I$123,Data!$D$2:$D$123,C$19,Data!$F$2:$F$123,12) -> 2146315.2
A34: Outlet performance (YTD Jan-Jun)
A35: Outlet | B35: Type | C35: Location | D35: Size m2 | E35: Sales 2024 | F35: Sales 2025 | G35: Sales 2026 | H35: YoY 26v25 | I35: Txns 2026 | J35: ATV 2026 | K35: Sales/m2 2026
A36: Gate Bistro | B36: =INDEX(Data!$B$2:$B$123,MATCH($A36,Data!$A$2:$A$123,0)) -> Coffee | C36: =INDEX(Data!$C$2:$C$123,MATCH($A36,Data!$A$2:$A$123,0)) -> Central | D36: =_xlfn.MAXIFS(Data!$G$2:$G$123,Data!$A$2:$A$123,$A36) -> 398 | E36: =SUMIFS(Data!$I$2:$I$123,Data!$A$2:$A$123,$A36,Data!$D$2:$D$123,2024,Data!$F$2:$F$123,"<=6") -> 0 | F36: =SUMIFS(Data!$I$2:$I$123,Data!$A$2:$A$123,$A36,Data!$D$2:$D$123,2025,Data!$F$2:$F$123,"<=6") -> 1868250.6 | G36: =SUMIFS(Data!$I$2:$I$123,Data!$A$2:$A$123,$A36,Data!$D$2:$D$123,2026,Data!$F$2:$F$123,"<=6") -> 1644137.6 | H36: =IF(F36=0,"new",G36/F36-1) -> -0.11995873 | I36: =SUMIFS(Data!$H$2:$H$123,Data!$A$2:$A$123,$A36,Data!$D$2:$D$123,2026,Data!$F$2:$F$123,"<=6") -> 109213.57 | J36: =IF(I36=0,0,G36/I36) -> 15.054334 | K36: =IF(D36=0,0,G36/D36) -> 4130.999
A37: Terminal Kitchen | B37: =INDEX(Data!$B$2:$B$123,MATCH($A37,Data!$A$2:$A$123,0)) -> Restaurants | C37: =INDEX(Data!$C$2:$C$123,MATCH($A37,Data!$A$2:$A$123,0)) -> East | D37: =_xlfn.MAXIFS(Data!$G$2:$G$123,Data!$A$2:$A$123,$A37) -> 300 | E37: =SUMIFS(Data!$I$2:$I$123,Data!$A$2:$A$123,$A37,Data!$D$2:$D$123,2024,Data!$F$2:$F$123,"<=6") -> 2383579.5 | F37: =SUMIFS(Data!$I$2:$I$123,Data!$A$2:$A$123,$A37,Data!$D$2:$D$123,2025,Data!$F$2:$F$123,"<=6") -> 2189201.6 | G37: =SUMIFS(Data!$I$2:$I$123,Data!$A$2:$A$123,$A37,Data!$D$2:$D$123,2026,Data!$F$2:$F$123,"<=6") -> 1897071.5 | H37: =IF(F37=0,"new",G37/F37-1) -> -0.13344141 | I37: =SUMIFS(Data!$H$2:$H$123,Data!$A$2:$A$123,$A37,Data!$D$2:$D$123,2026,Data!$F$2:$F$123,"<=6") -> 152141.36 | J37: =IF(I37=0,0,G37/I37) -> 12.469137 | K37: =IF(D37=0,0,G37/D37) -> 6323.5716
A38: Oak Coffee Bar | B38: =INDEX(Data!$B$2:$B$123,MATCH($A38,Data!$A$2:$A$123,0)) -> Coffee | C38: =INDEX(Data!$C$2:$C$123,MATCH($A38,Data!$A$2:$A$123,0)) -> West | D38: =_xlfn.MAXIFS(Data!$G$2:$G$123,Data!$A$2:$A$123,$A38) -> 269 | E38: =SUMIFS(Data!$I$2:$I$123,Data!$A$2:$A$123,$A38,Data!$D$2:$D$123,2024,Data!$F$2:$F$123,"<=6") -> 766717.72 | F38: =SUMIFS(Data!$I$2:$I$123,Data!$A$2:$A$123,$A38,Data!$D$2:$D$123,2025,Data!$F$2:$F$123,"<=6") -> 1494078.7 | G38: =SUMIFS(Data!$I$2:$I$123,Data!$A$2:$A$123,$A38,Data!$D$2:$D$123,2026,Data!$F$2:$F$123,"<=6") -> 1871420.7 | H38: =IF(F38=0,"new",G38/F38-1) -> 0.25255834 | I38: =SUMIFS(Data!$H$2:$H$123,Data!$A$2:$A$123,$A38,Data!$D$2:$D$123,2026,Data!$F$2:$F$123,"<=6") -> 228337.71 | J38: =IF(I38=0,0,G38/I38) -> 8.195846 | K38: =IF(D38=0,0,G38/D38) -> 6956.9543
A39: Sky Deli | B39: =INDEX(Data!$B$2:$B$123,MATCH($A39,Data!$A$2:$A$123,0)) -> Restaurants | C39: =INDEX(Data!$C$2:$C$123,MATCH($A39,Data!$A$2:$A$123,0)) -> Central | D39: =_xlfn.MAXIFS(Data!$G$2:$G$123,Data!$A$2:$A$123,$A39) -> 343 | E39: =SUMIFS(Data!$I$2:$I$123,Data!$A$2:$A$123,$A39,Data!$D$2:$D$123,2024,Data!$F$2:$F$123,"<=6") -> 0 | F39: =SUMIFS(Data!$I$2:$I$123,Data!$A$2:$A$123,$A39,Data!$D$2:$D$123,2025,Data!$F$2:$F$123,"<=6") -> 430677.82 | G39: =SUMIFS(Data!$I$2:$I$123,Data!$A$2:$A$123,$A39,Data!$D$2:$D$123,2026,Data!$F$2:$F$123,"<=6") -> 857627.77 | H39: =IF(F39=0,"new",G39/F39-1) -> 0.99134418 | I39: =SUMIFS(Data!$H$2:$H$123,Data!$A$2:$A$123,$A39,Data!$D$2:$D$123,2026,Data!$F$2:$F$123,"<=6") -> 47019.57 | J39: =IF(I39=0,0,G39/I39) -> 18.239805 | K39: =IF(D39=0,0,G39/D39) -> 2500.3725
A40: North Kitchen | B40: =INDEX(Data!$B$2:$B$123,MATCH($A40,Data!$A$2:$A$123,0)) -> Restaurants | C40: =INDEX(Data!$C$2:$C$123,MATCH($A40,Data!$A$2:$A$123,0)) -> East | D40: =_xlfn.MAXIFS(Data!$G$2:$G$123,Data!$A$2:$A$123,$A40) -> 817 | E40: =SUMIFS(Data!$I$2:$I$123,Data!$A$2:$A$123,$A40,Data!$D$2:$D$123,2024,Data!$F$2:$F$123,"<=6") -> 6897862.1 | F40: =SUMIFS(Data!$I$2:$I$123,Data!$A$2:$A$123,$A40,Data!$D$2:$D$123,2025,Data!$F$2:$F$123,"<=6") -> 7273248.9 | G40: =SUMIFS(Data!$I$2:$I$123,Data!$A$2:$A$123,$A40,Data!$D$2:$D$123,2026,Data!$F$2:$F$123,"<=6") -> 8151500.8 | H40: =IF(F40=0,"new",G40/F40-1) -> 0.12075098 | I40: =SUMIFS(Data!$H$2:$H$123,Data!$A$2:$A$123,$A40,Data!$D$2:$D$123,2026,Data!$F$2:$F$123,"<=6") -> 545540.49 | J40: =IF(I40=0,0,G40/I40) -> 14.942064 | K40: =IF(D40=0,0,G40/D40) -> 9977.3572
A41: Total | E41: =SUM(E36:E40) -> 10048159 | F41: =SUM(F36:F40) -> 13255458 | G41: =SUM(G36:G40) -> 14421758 | I41: =SUM(I36:I40) -> 1082252.7
A44: Selected outlet monthly sales
A45: Outlet: | B45: =Dashboard!B4 -> Gate Bistro
A46: Month | B46: 2024 | C46: 2025 | D46: 2026
A47: Jan | B47: =SUMIFS(Data!$I$2:$I$123,Data!$A$2:$A$123,$B$45,Data!$D$2:$D$123,B$46,Data!$F$2:$F$123,1) -> 0 | C47: =SUMIFS(Data!$I$2:$I$123,Data!$A$2:$A$123,$B$45,Data!$D$2:$D$123,C$46,Data!$F$2:$F$123,1) -> 228691.06 | D47: =SUMIFS(Data!$I$2:$I$123,Data!$A$2:$A$123,$B$45,Data!$D$2:$D$123,D$46,Data!$F$2:$F$123,1) -> 292270.14
...

Sheet Dashboard
A1: Catering Dashboard
A2: Monthly sales, Jan 2024 - Jun 2026. Figures link to the Output tab.
A4: Outlet: | B4: Gate Bistro | C4: (Use dropdown)
A6: Headline (YTD Jan-Jun 2026)
A7: YTD Sales | B7: =Output!D12 -> 14421758
A8: YoY vs 2025 | B8: =Output!F12 -> 0.087986464
A9: Transactions | B9: =Output!D13 -> 1082252.7
A10: ATV | B10: =Output!D14 -> 13.325685
A11: Spend per passenger | B11: =Output!D16 -> 1.7601493

Sheet Summary
A1: Key findings
A3: - Catering sales are growing but slowing. On a like-for-like Jan-Jun basis, sales went from £10.0m (2024) to £13.3m (2025, +32%) to £14.4m (2026, +9%). I compared Jan-Jun only because 2026 has no data past June.
A4: - North Kitchen is by far the biggest outlet (about £8.2m YTD 2026, over half of all sales) and is still growing.
A5: - Terminal Kitchen is the only outlet going backwards (£2.4m -> £2.2m -> £1.9m YTD). Its transactions dropped sharply in Jan-Feb 2026, which is worth looking into.
A6: - The two newer outlets (Gate Bistro from Dec 2024, Sky Deli from May 2025) add most of the growth, so underlying growth in existing outlets is smaller.
A7: - One likely data error: Terminal Kitchen Aug-2024 shows £5.16m with an ATV around £134 (roughly 10x normal). I left it in but flagged it; it doesn't affect the Jan-Jun comparison.
